Workbook

Sheet RESUMEN
A1: RESUMEN DE CARTERA — POSICIÓN Y RESULTADO
A3: Tipo de cambio €/$ | B3: 0.85
A4: Fecha de los precios | B4: =PRECIOS!D2 -> 46265
A6: CARTERA — TU CAPITAL
A7: TOKEN | B7: CANTIDAD | C7: COSTE (USD) | D7: PRECIO MEDIO | E7: PRECIO ACTUAL | F7: VALOR (USD) | G7: P&L (USD) | H7: P&L %
A8: BTC | B8: =SUMIFS(Movimientos[CANTIDAD],Movimientos[TOKEN],$A8) -> 0.014246 | C8: =SUMIFS(Movimientos[TOTAL (USD)],Movimientos[TOKEN],$A8) -> 879.44 | D8: =IF(B8=0,"",C8/B8) -> 61732.416 | E8: =_xlfn.XLOOKUP($A8,Precios[TOKEN],Precios[PRECIO (USD)]) -> 80041.72 | F8: =B8*E8 -> 1140.2743 | G8: =F8-C8 -> 260.83434 | H8: =IF(C8=0,"",G8/C8) -> 0.2965914
A9: ETH | B9: =SUMIFS(Movimientos[CANTIDAD],Movimientos[TOKEN],$A9) -> 0.5145 | C9: =SUMIFS(Movimientos[TOTAL (USD)],Movimientos[TOKEN],$A9) -> 968.17326 | D9: =IF(B9=0,"",C9/B9) -> 1881.7751 | E9: =_xlfn.XLOOKUP($A9,Precios[TOKEN],Precios[PRECIO (USD)]) -> 2488.52 | F9: =B9*E9 -> 1280.3435 | G9: =F9-C9 -> 312.17028 | H9: =IF(C9=0,"",G9/C9) -> 0.32243224
A10: ATOM | B10: =SUMIFS(Movimientos[CANTIDAD],Movimientos[TOKEN],$A10) -> 713.68 | C10: =SUMIFS(Movimientos[TOTAL (USD)],Movimientos[TOKEN],$A10) -> 1123.15 | D10: =IF(B10=0,"",C10/B10) -> 1.5737445 | E10: =_xlfn.XLOOKUP($A10,Precios[TOKEN],Precios[PRECIO (USD)]) -> 1.5441 | F10: =B10*E10 -> 1101.9933 | G10: =F10-C10 -> -21.156712 | H10: =IF(C10=0,"",G10/C10) -> -0.018836943
A11: TIA | B11: =SUMIFS(Movimientos[CANTIDAD],Movimientos[TOKEN],$A11) -> 423.85 | C11: =SUMIFS(Movimientos[TOTAL (USD)],Movimientos[TOKEN],$A11) -> 213.47 | D11: =IF(B11=0,"",C11/B11) -> 0.50364516 | E11: =_xlfn.XLOOKUP($A11,Precios[TOKEN],Precios[PRECIO (USD)]) -> 0.3756 | F11: =B11*E11 -> 159.19806 | G11: =F11-C11 -> -54.27194 | H11: =IF(C11=0,"",G11/C11) -> -0.25423685
A12: TOTAL | C12: =SUM(C8:C11) -> 3184.2333 | F12: =SUM(F8:F11) -> 3681.8092 | G12: =SUM(G8:G11) -> 497.57597 | H12: =IF(C12=0,"",G12/C12) -> 0.15626241
A14: AIRDROPS / STAKING — sin capital invertido (informativo)
A15: TOKEN | B15: CANTIDAD | E15: PRECIO ACTUAL | F15: VALOR (USD) | G15: NOTA
A16: PI | B16: =SUMIFS(Movimientos[CANTIDAD],Movimientos[TOKEN],$A16) -> 969.79 | E16: =_xlfn.XLOOKUP($A16,Precios[TOKEN],Precios[PRECIO (USD)]) -> 0.08997 | F16: =B16*E16 -> 87.252006 | G16: Bloqueado ~4 años (minado móvil)
A17: ATONE | B17: =SUMIFS(Movimientos[CANTIDAD],Movimientos[TOKEN],$A17) -> 13.27 | E17: =_xlfn.XLOOKUP($A17,Precios[TOKEN],Precios[PRECIO (USD)]) -> 0.1357 | F17: =B17*E17 -> 1.800739 | G17: Airdrop / staking
A18: MODE | B18: =SUMIFS(Movimientos[CANTIDAD],Movimientos[TOKEN],$A18) -> 1271 | E18: =_xlfn.XLOOKUP($A18,Precios[TOKEN],Precios[PRECIO (USD)]) -> 7.056e-05 | F18: =B18*E18 -> 0.08968176 | G18: Airdrop
A20: RESULTADO (orientativo) | D20: ✓ OFICIAL HACIENDA (CoinMarketCap)
A21: Coste total (USD) | B21: =C12 -> 3184.2333 | D21: Coste base (USD) | E21: 3110.38
A22: Valor cartera (USD) | B22: =F12 -> 3681.8092 | D22: Valor actual (USD) | E22: 3771
A23: Valor airdrops (USD) | B23: =SUM(F16:F18) -> 89.142427 | D23: Beneficio total (USD) | E23: 660.62
A24: Valor total (USD) | B24: =F12+SUM(F16:F18) -> 3770.9517 | D24: Beneficio % | E24: 0.2124
A25: P&L total (USD) | B25: =B24-B21 -> 586.71839
A26: P&L % | B26: =IF(B21=0,"",B25/B21) -> 0.18425735 | D26: Cifra oficial: sale de las transacciones reales del tracker.
A27: P&L total (€) | B27: =B25*$B$3 -> 498.71064
A30: COMPRAS HISTÓRICAS — no en cartera actual (registro para Hacienda)
A31: TOKEN | B31: COSTE REGISTRADO (€)
A32: DOT | B32: =SUMIFS('2025'!$B:$B,'2025'!$D:$D,$A32)+SUMIFS('2025'!$C:$C,'2025'!$D:$D,$A32)+SUMIFS('2026'!$B:$B,'2026'!$D:$D,$A32)+SUMIFS('2026'!$C:$C,'2026'!$D:$D,$A32) -> 126.46
A33: AVAX | B33: =SUMIFS('2025'!$B:$B,'2025'!$D:$D,$A33)+SUMIFS('2025'!$C:$C,'2025'!$D:$D,$A33)+SUMIFS('2026'!$B:$B,'2026'!$D:$D,$A33)+SUMIFS('2026'!$C:$C,'2026'!$D:$D,$A33) -> 164.06
A34: NEAR | B34: =SUMIFS('2025'!$B:$B,'2025'!$D:$D,$A34)+SUMIFS('2025'!$C:$C,'2025'!$D:$D,$A34)+SUMIFS('2026'!$B:$B,'2026'!$D:$D,$A34)+SUMIFS('2026'!$C:$C,'2026'!$D:$D,$A34) -> 76.46 | D34: si
A35: BNB | B35: =SUMIFS('2025'!$B:$B,'2025'!$D:$D,$A35)+SUMIFS('2025'!$C:$C,'2025'!$D:$D,$A35)+SUMIFS('2026'!$B:$B,'2026'!$D:$D,$A35)+SUMIFS('2026'!$C:$C,'2026'!$D:$D,$A35) -> 142.93
A36: THE | B36: =SUMIFS('2025'!$B:$B,'2025'!$D:$D,$A36)+SUMIFS('2025'!$C:$C,'2025'!$D:$D,$A36)+SUMIFS('2026'!$B:$B,'2026'!$D:$D,$A36)+SUMIFS('2026'!$C:$C,'2026'!$D:$D,$A36) -> 102
A37: LINEA | B37: =SUMIFS('2025'!$B:$B,'2025'!$D:$D,$A37)+SUMIFS('2025'!$C:$C,'2025'!$D:$D,$A37)+SUMIFS('2026'!$B:$B,'2026'!$D:$D,$A37)+SUMIFS('2026'!$C:$C,'2026'!$D:$D,$A37) -> 238
A38: BGB | B38: =SUMIFS('2025'!$B:$B,'2025'!$D:$D,$A38)+SUMIFS('2025'!$C:$C,'2025'!$D:$D,$A38)+SUMIFS('2026'!$B:$B,'2026'!$D:$D,$A38)+SUMIFS('2026'!$C:$C,'2026'!$D:$D,$A38) -> 102
A39: BIT2ME | B39: =SUMIFS('2025'!$B:$B,'2025'!$D:$D,$A39)+SUMIFS('2025'!$C:$C,'2025'!$D:$D,$A39)+SUMIFS('2026'!$B:$B,'2026'!$D:$D,$A39)+SUMIFS('2026'!$C:$C,'2026'!$D:$D,$A39) -> 259
A40: USDC | B40: =SUMIFS('2025'!$B:$B,'2025'!$D:$D,$A40)+SUMIFS('2025'!$C:$C,'2025'!$D:$D,$A40)+SUMIFS('2026'!$B:$B,'2026'!$D:$D,$A40)+SUMIFS('2026'!$C:$C,'2026'!$D:$D,$A40) -> 665.48
A41: TOTAL | B41: =SUM(B32:B40) -> 1876.39

Sheet PLAN Y RIESGOS
A1: PLAN DE INVERSIÓN Y ANÁLISIS DE RIESGOS
A2: Cartera cripto de Nando · asesoramiento educativo, no es recomendación financiera
A4: 1 · FOTO ACTUAL DE TU CARTERA
A5: ACTIVO | B5: VALOR (€) | C5: % CARTERA | D5: CATEGORÍA | E5: NIVEL DE RIESGO
A6: Bitcoin (BTC) | B6: =RESUMEN!F8*RESUMEN!B3 -> 969.23319 | C6: =IF($B$11=0,"",B6/$B$11) -> 0.30238371 | D6: Large-cap | E6: Moderado
A7: Ethereum (ETH) | B7: =RESUMEN!F9*RESUMEN!B3 -> 1088.292 | C7: =IF($B$11=0,"",B7/$B$11) -> 0.33952796 | D7: Large-cap | E7: Moderado
A8: Cosmos (ATOM) | B8: =RESUMEN!F10*RESUMEN!B3 -> 936.69429 | C8: =IF($B$11=0,"",B8/$B$11) -> 0.29223214 | D8: Alt (Cosmos) | E8: Alto
A9: Celestia (TIA) | B9: =RESUMEN!F11*RESUMEN!B3 -> 135.31835 | C9: =IF($B$11=0,"",B9/$B$11) -> 0.042216945 | D9: Alt (Cosmos) | E9: Muy alto
A10: Airdrops (PI/ATONE/MODE) | B10: =SUM(RESUMEN!F16:F18)*RESUMEN!B3 -> 75.771063 | C10: =IF($B$11=0,"",B10/$B$11) -> 0.023639239 | D10: Especulativo | E10: Muy alto
A11: TOTAL | B11: =SUM(B6:B10) -> 3205.3089 | C11: =IF($B$11=0,"",B11/$B$11) -> 1
A13: 2 · DIAGNÓSTICO DE RIESGOS
A14: Peso en large-cap (BTC + ETH) | B14: =(B6+B7)/B11 -> 0.64191167 | C14: Base más sólida y líquida de la cartera
A15: Peso en alts (ATOM + TIA) | B15: =(B8+B9)/B11 -> 0.33444909 | C15: Más potencial pero mucha más volatilidad
A16: Concentración Cosmos (ATOM+TIA) | B16: =(B8+B9)/B11 -> 0.33444909 | C16: ⚠ Riesgo de correlación: tienden a subir y bajar juntas
A17: Mayor posición individual | B17: =MAX(B6:B9)/B11 -> 0.33952796 | C17: Cuanto más alto, más dependes de un solo activo
A18: Airdrops (valor especulativo) | B18: =B10/B11 -> 0.023639239 | C18: Coste 0 €; PI bloqueado ~4 años. No cuentes con ello
A19: VEREDICTO: Base sólida — el 64% está en BTC+ETH, que es lo correcto para una cartera pequeña. PERO un tercio está concentrado en el ecosistema Cosmos (ATOM+TIA): se mueven muy correlacionadas, así que si Cosmos flojea, pierdes por partida doble, y TIA es de lo más volátil que tienes. Además no tienes stablecoins = no tienes 'pólvora seca' para aprovechar las caídas. Plan: mantener el núcleo BTC/ETH, no dejar que Cosmos crezca más del ~25-30%, y abrir un pequeño colchón en USDC para comprar en los desplomes.
A23: 3 · CÓMO REPARTIR TUS 175 €/MES
A24: Aportación mensual (€) | B24: 175 | C24: ← cambia este número y todo el plan se recalcula
A25: ACTIVO | B25: PESO OBJETIVO | C25: APORTA (€/mes) | D25: PESO ACTUAL | E25: QUÉ HACER
A26: Bitcoin (BTC) | B26: 0.4 | C26: =B26*$B$24 -> 70 | D26: =C6 -> 0.30238371 | E26: =IF(D26<B26,"Reforzar","Suficiente") -> Reforzar
A27: Ethereum (ETH) | B27: 0.3 | C27: =B27*$B$24 -> 52.5 | D27: =C7 -> 0.33952796 | E27: =IF(D27<B27,"Reforzar","Suficiente") -> Suficiente
A28: Cosmos (ATOM) | B28: 0.15 | C28: =B28*$B$24 -> 26.25 | D28: =C8 -> 0.29223214 | E28: =IF(D28<B28,"Reforzar","Suficiente") -> Suficiente
A29: Celestia (TIA) | B29: 0.1 | C29: =B29*$B$24 -> 17.5 | D29: =C9 -> 0.042216945 | E29: =IF(D29<B29,"Reforzar","Suficiente") -> Reforzar
A30: USDC (colchón) | B30: 0.05 | C30: =B30*$B$24 -> 8.75 | D30: 0 | E30: =IF(D30<B30,"Reforzar","Suficiente") -> Reforzar
A31: TOTAL | B31: =SUM(B26:B30) -> 1 | C31: =SUM(C26:C30) -> 175
A32: Por qué este reparto: 70% en BTC+ETH (el núcleo, menos volátil) y 25% en tus alts (ATOM+TIA, más riesgo/recompensa) sin pasarte de ahí, más un 5% en USDC que vas acumulando para comprar en las caídas fuertes. Aportando siempre lo mismo cada mes (DCA) compras más barato cuando cae y evitas intentar adivinar el mejor momento. Ajusta los % azules a tu gusto: el reparto en € se recalcula solo.
A35: 4 · PROYECCIÓN SI MANTIENES EL PLAN
A36: Valor de partida hoy (€) | B36: =B11*RESUMEN!B3 -> 2724.5126 | C36: Aportando 175 €/mes de forma constante (DCA)
A38: HORIZONTE | B38: CONSERVADOR | C38: BASE (realista) | D38: OPTIMISTA | E38: TOTAL APORTADO
A39: Rentabilidad anual → | B39: 0.05 | C39: 0.15 | D39: 0.3
A40: 1 | B40: =FV(B$39/12,$A40*12,-$B$24,-$B$36) -> 5012.7035 | C40: =FV(C$39/12,$A40*12,-$B$24,-$B$36) -> 5413.0535 | D40: =FV(D$39/12,$A40*12,-$B$24,-$B$36) -> 6078.3883 | E40: =$B$36+$B$24*12*$A40 -> 4824.5126
A41: 3 | B41: =FV(B$39/12,$A41*12,-$B$24,-$B$36) -> 9946.2794 | C41: =FV(C$39/12,$A41*12,-$B$24,-$B$36) -> 12156.198 | D41: =FV(D$39/12,$A41*12,-$B$24,-$B$36) -> 16655.22 | E41: =$B$36+$B$24*12*$A41 -> 9024.5126
A42: 5 | B42: =FV(B$39/12,$A42*12,-$B$24,-$B$36) -> 15397.591 | C42: =FV(C$39/12,$A42*12,-$B$24,-$B$36) -> 21241.581 | D42: =FV(D$39/12,$A42*12,-$B$24,-$B$36) -> 35785.811 | E42: =$B$36+$B$24*12*$A42 -> 13224.513
A43: 10 | B43: =FV(B$39/12,$A43*12,-$B$24,-$B$36) -> 31661.697 | C43: =FV(C$39/12,$A43*12,-$B$24,-$B$36) -> 60260.402 | D43: =FV(D$39/12,$A43*12,-$B$24,-$B$36) -> 181248.57 | E43: =$B$36+$B$24*12*$A43 -> 23724.513
A45: 5 · REGLAS DE ORO
A46: 1. Fondo de emergencia PRIMERO: ten 3–6 meses de gastos en efectivo antes de meter nada en cripto. 2. Solo invierte lo que puedas permitirte perder. La cripto puede caer un 70–80% en un mal año — que no te pille apalancado ni con dinero que necesitas. 3. DCA siempre: los mismos 175 €/mes pase lo que pase. No intentes adivinar el suelo ni el techo. 4. No persigas pumps: si algo ya ha subido 5x, no es el momento de entrar a lo loco. 5. Rebalancea cada 3–6 meses: si un activo se dispara y rompe tu %, vende un poco y vuelve al objetivo. 6. Toma beneficios en la euforia: en un bull fuerte, pasa parte a USDC/€. Nadie ha quebrado por tomar ganancias. 7. Seguridad: activa 2FA y, según acumules, plantéate una hardware wallet. No dejes todo en el exchange. 8. Hacienda: cada venta o cambio de token tributa. Guarda el registro (ya lo tienes en las hojas 2025/2026).
A55: 6 · CUSTODIA Y SEGURIDAD (dónde está tu dinero)
A56: UBICACIÓN | B56: TIPO | C56: IMPORTE (€) | D56: % CARTERA | E56: PARA QUÉ
A57: Bit2Me | B57: Exchange (regulado ES) | C57: 1068 | D57: =IF($C$60=0,"",C57/$C$60) -> 0.33333333 | E57: Puente a euros y declarar a Hacienda
...

Sheet MOVIMIENTOS
A1: FECHA | B1: TOKEN | C1: CLASE | D1: PRECIO (USD) | E1: CANTIDAD | F1: TOTAL (USD) | G1: COSTE (€) | H1: OBSERVACIONES
A2: 45325 | B2: BTC | C2: Compra | D2: 43.18 | E2: 0.000532 | F2: 0.02 | G2: =F2*RESUMEN!$B$3 -> 0.017
A3: 45350 | B3: BTC | C3: Compra | D3: 0 | E3: 0.00023 | F3: 0 | G3: =F3*RESUMEN!$B$3 -> 0
A4: 45551 | B4: MODE | C4: Compra | D4: 0 | E4: 349 | F4: 0 | G4: =F4*RESUMEN!$B$3 -> 0
A5: 45551 | B5: MODE | C5: Compra | D5: 0 | E5: 676 | F5: 0 | G5: =F5*RESUMEN!$B$3 -> 0
A6: 45586 | B6: MODE | C6: Compra | D6: 0 | E6: 246 | F6: 0 | G6: =F6*RESUMEN!$B$3 -> 0
A7: 45901 | B7: PI | C7: Compra | D7: 0 | E7: 969.79 | F7: 0 | G7: =F7*RESUMEN!$B$3 -> 0
A8: 45901 | B8: ETH | C8: Compra | D8: 1539.8 | E8: 0.274 | F8: 421.91 | G8: =F8*RESUMEN!$B$3 -> 358.6235
A9: 45902 | B9: ETH | C9: Compra | D9: 4629.12 | E9: 0.0192 | F9: =D9*E9 -> 88.879104 | G9: =F9*RESUMEN!$B$3 -> 75.547238
A10: 45931 | B10: ETH | C10: Compra | D10: 4629.12 | E10: 0.018 | F10: =D10*E10 -> 83.32416 | G10: =F10*RESUMEN!$B$3 -> 70.825536
A11: 45945 | B11: ATONE | C11: Airdrop | D11: 0 | E11: 10.27 | F11: 0 | G11: =F11*RESUMEN!$B$3 -> 0
A12: 45961 | B12: ATOM | C12: Compra | D12: 2.9952 | E12: 18.19 | F12: 54.48 | G12: =F12*RESUMEN!$B$3 -> 46.308
A13: 45961 | B13: TIA | C13: Compra | D13: 0.9103 | E13: 56.25 | F13: 51.2 | G13: =F13*RESUMEN!$B$3 -> 43.52
A14: 45965 | B14: TIA | C14: Compra | D14: 0.57 | E14: 31 | F14: 17.67 | G14: =F14*RESUMEN!$B$3 -> 15.0195
A15: 45997 | B15: TIA | C15: Compra | D15: 0.5765 | E15: 60.46 | F15: 34.86 | G15: =F15*RESUMEN!$B$3 -> 29.631
A16: 45997 | B16: ATOM | C16: Compra | D16: 2.2432 | E16: 9.25 | F16: 20.75 | G16: =F16*RESUMEN!$B$3 -> 17.6375
A17: 45997 | B17: ATOM | C17: Compra | D17: 2.2432 | E17: 15.53 | F17: 34.84 | G17: =F17*RESUMEN!$B$3 -> 29.614
A18: 46049 | B18: TIA | C18: Compra | D18: 0.438 | E18: 136 | F18: 59.58 | G18: =F18*RESUMEN!$B$3 -> 50.643
A19: 46049 | B19: ATOM | C19: Compra | D19: 2.2049 | E19: 27 | F19: 59.53 | G19: =F19*RESUMEN!$B$3 -> 50.6005
A20: 46080 | B20: BTC | C20: Compra | D20: 65992.28 | E20: 0.001714 | F20: 113.11 | G20: =F20*RESUMEN!$B$3 -> 96.1435
A21: 46082 | B21: BTC | C21: Compra | D21: 66557.79 | E21: 0.0031 | F21: 206.33 | G21: =F21*RESUMEN!$B$3 -> 175.3805
A22: 46114 | B22: ATOM | C22: Compra | D22: 1.6438 | E22: 30 | F22: 49.31 | G22: =F22*RESUMEN!$B$3 -> 41.9135
... A41: 46234 | B41: BTC | C41: Compra | D41: 63885.09 | E41: 0.0012 | F41: 76.66 | G41: =F41*RESUMEN!$B$3 -> 65.161

Sheet PRECIOS
A1: TOKEN | B1: PRECIO (USD) | C1: FUENTE | D1: FECHA
A2: BTC | B2: 80041.72 | C2: CoinMarketCap | D2: 46265
A3: ETH | B3: 2488.52 | C3: CoinMarketCap | D3: 46265
A4: ATOM | B4: 1.5441 | C4: CoinMarketCap | D4: 46265
A5: TIA | B5: 0.3756 | C5: CoinMarketCap | D5: 46265
A6: PI | B6: 0.08997 | C6: CoinMarketCap | D6: 46265
A7: ATONE | B7: 0.1357 | C7: CoinMarketCap | D7: 46265
A8: MODE | B8: 7.056e-05 | C8: CoinMarketCap | D8: 46265
A10: Edita aquí los precios (columna azul). RESUMEN los lee con BUSCARX. Para auto-actualizar: Datos > Desde web con la API de CoinGecko y vuelca aquí.

Sheet 2025
A2: TRAZABILIDAD Y CONTABILIDAD | G2: TOTAL INVERTIDO (€ / $) | J2: VALOR CARTERA HOY
A3: COMPRAS | G3: =SUM(Tabla1[EUROS])+SUM(Tabla1[COMISION]) -> 1401.28 | H3: =G3/RESUMEN!$B$3 -> 1648.5647 | J3: =RESUMEN!$B$24*RESUMEN!$B$3 -> 3205.3089 | K3: =RESUMEN!$B$24 -> 3770.9517
A4: FECHA | B4: EUROS | C4: COMISION | D4: MONEDA | E4: CANTIDAD | F4: COSTE UNITARIO (€)
A5: 45874 | B5: 100 | C5: 2 | D5: BNB | E5: 0.15 | F5: =IF(Tabla1[[#This Row],[CANTIDAD]]=0,"",(Tabla1[[#This Row],[EUROS]]+Tabla1[[#This Row],[COMISION]])/Tabla1[[#This Row],[CANTIDAD]]) -> 680 | G5: AIRDROPS
A6: 45874 | B6: 100 | C6: 2 | D6: BGB | E6: 25.68 | F6: =IF(Tabla1[[#This Row],[CANTIDAD]]=0,"",(Tabla1[[#This Row],[EUROS]]+Tabla1[[#This Row],[COMISION]])/Tabla1[[#This Row],[CANTIDAD]]) -> 3.9719626 | G6: TOKEN | H6: PRECIO
A7: 45887 | B7: 140 | C7: 2 | D7: USDC | E7: 160 | F7: =IF(Tabla1[[#This Row],[CANTIDAD]]=0,"",(Tabla1[[#This Row],[EUROS]]+Tabla1[[#This Row],[COMISION]])/Tabla1[[#This Row],[CANTIDAD]]) -> 0.8875 | G7: LINEA | H7: 238
A8: 45901 | B8: 75 | C8: 2 | D8: ETH | E8: 0.0192 | F8: =IF(Tabla1[[#This Row],[CANTIDAD]]=0,"",(Tabla1[[#This Row],[EUROS]]+Tabla1[[#This Row],[COMISION]])/Tabla1[[#This Row],[CANTIDAD]]) -> 4010.4167
A9: 45901 | B9: 74 | C9: 2 | D9: USDC | E9: 83.8 | F9: =IF(Tabla1[[#This Row],[CANTIDAD]]=0,"",(Tabla1[[#This Row],[EUROS]]+Tabla1[[#This Row],[COMISION]])/Tabla1[[#This Row],[CANTIDAD]]) -> 0.90692124
A10: 45902 | B10: 100 | C10: 2 | D10: THE | E10: 337.24 | F10: =IF(Tabla1[[#This Row],[CANTIDAD]]=0,"",(Tabla1[[#This Row],[EUROS]]+Tabla1[[#This Row],[COMISION]])/Tabla1[[#This Row],[CANTIDAD]]) -> 0.30245522
A11: 45911 | B11: 238 | C11: 0 | D11: LINEA | E11: 12000.13 | F11: =IF(Tabla1[[#This Row],[CANTIDAD]]=0,"",(Tabla1[[#This Row],[EUROS]]+Tabla1[[#This Row],[COMISION]])/Tabla1[[#This Row],[CANTIDAD]]) -> 0.019833118
A12: 45931 | B12: 120 | C12: 0 | D12: ETH | E12: 0.0329 | F12: =IF(Tabla1[[#This Row],[CANTIDAD]]=0,"",(Tabla1[[#This Row],[EUROS]]+Tabla1[[#This Row],[COMISION]])/Tabla1[[#This Row],[CANTIDAD]]) -> 3647.4164
A13: 45931 | B13: 80 | C13: 0.48 | D13: USDC | E13: 92 | F13: =IF(Tabla1[[#This Row],[CANTIDAD]]=0,"",(Tabla1[[#This Row],[EUROS]]+Tabla1[[#This Row],[COMISION]])/Tabla1[[#This Row],[CANTIDAD]]) -> 0.87478261
A14: 45961 | B14: 50 | C14: 3 | D14: ATOM | E14: 18.19 | F14: =IF(Tabla1[[#This Row],[CANTIDAD]]=0,"",(Tabla1[[#This Row],[EUROS]]+Tabla1[[#This Row],[COMISION]])/Tabla1[[#This Row],[CANTIDAD]]) -> 2.9136888
A15: 45961 | B15: 46 | C15: 0.92 | D15: TIA | E15: 56.31 | F15: =IF(Tabla1[[#This Row],[CANTIDAD]]=0,"",(Tabla1[[#This Row],[EUROS]]+Tabla1[[#This Row],[COMISION]])/Tabla1[[#This Row],[CANTIDAD]]) -> 0.83324454
A16: 45961 | B16: 26 | C16: 0.46 | D16: NEAR | E16: 13.76 | F16: =IF(Tabla1[[#This Row],[CANTIDAD]]=0,"",(Tabla1[[#This Row],[EUROS]]+Tabla1[[#This Row],[COMISION]])/Tabla1[[#This Row],[CANTIDAD]]) -> 1.9229651
A17: 45961 | B17: 26 | C17: 0.46 | D17: DOT | E17: 9.9 | F17: =IF(Tabla1[[#This Row],[CANTIDAD]]=0,"",(Tabla1[[#This Row],[EUROS]]+Tabla1[[#This Row],[COMISION]])/Tabla1[[#This Row],[CANTIDAD]]) -> 2.6727273
A18: 45961 | B18: 48 | C18: 0.96 | D18: AVAX | E18: 2.94 | F18: =IF(Tabla1[[#This Row],[CANTIDAD]]=0,"",(Tabla1[[#This Row],[EUROS]]+Tabla1[[#This Row],[COMISION]])/Tabla1[[#This Row],[CANTIDAD]]) -> 16.653061
A19: 45997 | B19: 160 | C19: 0 | D19: USDC | E19: 182 | F19: =IF(Tabla1[[#This Row],[CANTIDAD]]=0,"",(Tabla1[[#This Row],[EUROS]]+Tabla1[[#This Row],[COMISION]])/Tabla1[[#This Row],[CANTIDAD]]) -> 0.87912088

Sheet 2026
A2: TRAZABILIDAD Y CONTABILIDAD | G2: TOTAL INVERTIDO (€ / $) | J2: VALOR CARTERA HOY
A3: COMPRAS | G3: =SUM(Tabla13[EUROS])+SUM(Tabla13[COMISION]) -> 1173.23 | H3: =G3/RESUMEN!$B$3 -> 1380.2706 | J3: =RESUMEN!$B$24*RESUMEN!$B$3 -> 3205.3089 | K3: =RESUMEN!$B$24 -> 3770.9517
A4: FECHA | B4: EUROS | C4: COMISION | D4: MONEDA | E4: CANTIDAD | F4: COSTE UNITARIO (€)
A5: 46023 | B5: 100 | C5: 0 | D5: DOT | E5: 65.4 | F5: =IF(Tabla13[[#This Row],[CANTIDAD]]=0,"",(Tabla13[[#This Row],[EUROS]]+Tabla13[[#This Row],[COMISION]])/Tabla13[[#This Row],[CANTIDAD]]) -> 1.529052 | G5: AIRDROPS
A6: 46023 | B6: 50 | C6: 0 | D6: AVAX | E6: 4.75 | F6: =IF(Tabla13[[#This Row],[CANTIDAD]]=0,"",(Tabla13[[#This Row],[EUROS]]+Tabla13[[#This Row],[COMISION]])/Tabla13[[#This Row],[CANTIDAD]]) -> 10.526316 | G6: TOKEN | H6: PRECIO
A7: 46050 | B7: 50 | C7: 0 | D7: TIA | E7: 136 | F7: =IF(Tabla13[[#This Row],[CANTIDAD]]=0,"",(Tabla13[[#This Row],[EUROS]]+Tabla13[[#This Row],[COMISION]])/Tabla13[[#This Row],[CANTIDAD]]) -> 0.36764706 | G7: LINEA | H7: 238
A8: 46050 | B8: 50 | C8: 0 | D8: NEAR | E8: 40.9 | F8: =IF(Tabla13[[#This Row],[CANTIDAD]]=0,"",(Tabla13[[#This Row],[EUROS]]+Tabla13[[#This Row],[COMISION]])/Tabla13[[#This Row],[CANTIDAD]]) -> 1.2224939
A9: 46050 | B9: 50 | C9: 0 | D9: ATOM | E9: 27 | F9: =IF(Tabla13[[#This Row],[CANTIDAD]]=0,"",(Tabla13[[#This Row],[EUROS]]+Tabla13[[#This Row],[COMISION]])/Tabla13[[#This Row],[CANTIDAD]]) -> 1.8518519
A10: 46080 | B10: 100 | C10: 3 | D10: BTC | E10: 0.001714 | F10: =IF(Tabla13[[#This Row],[CANTIDAD]]=0,"",(Tabla13[[#This Row],[EUROS]]+Tabla13[[#This Row],[COMISION]])/Tabla13[[#This Row],[CANTIDAD]]) -> 60093.349
A11: 46113 | B11: 43 | C11: 0.2 | D11: ATOM | E11: 30 | F11: =IF(Tabla13[[#This Row],[CANTIDAD]]=0,"",(Tabla13[[#This Row],[EUROS]]+Tabla13[[#This Row],[COMISION]])/Tabla13[[#This Row],[CANTIDAD]]) -> 1.44
A12: 46113 | B12: 65 | C12: 0.1 | D12: AVAX | E12: 8.5 | F12: =IF(Tabla13[[#This Row],[CANTIDAD]]=0,"",(Tabla13[[#This Row],[EUROS]]+Tabla13[[#This Row],[COMISION]])/Tabla13[[#This Row],[CANTIDAD]]) -> 7.6588235
A13: 46113 | B13: 40.93 | C13: 0 | D13: BNB | E13: 0.08 | F13: =IF(Tabla13[[#This Row],[CANTIDAD]]=0,"",(Tabla13[[#This Row],[EUROS]]+Tabla13[[#This Row],[COMISION]])/Tabla13[[#This Row],[CANTIDAD]]) -> 511.625
A14: 46133 | B14: 150 | C14: 5 | D14: ATOM | E14: 93.74 | F14: =IF(Tabla13[[#This Row],[CANTIDAD]]=0,"",(Tabla13[[#This Row],[EUROS]]+Tabla13[[#This Row],[COMISION]])/Tabla13[[#This Row],[CANTIDAD]]) -> 1.6535097
A15: 46175 | B15: 200 | C15: 7 | D15: USDC | E15: 212 | F15: =IF(Tabla13[[#This Row],[CANTIDAD]]=0,"",(Tabla13[[#This Row],[EUROS]]+Tabla13[[#This Row],[COMISION]])/Tabla13[[#This Row],[CANTIDAD]]) -> 0.97641509
A16: 46205 | B16: 100 | C16: 4 | D16: BIT2ME | E16: 19500 | F16: =IF(Tabla13[[#This Row],[CANTIDAD]]=0,"",(Tabla13[[#This Row],[EUROS]]+Tabla13[[#This Row],[COMISION]])/Tabla13[[#This Row],[CANTIDAD]]) -> 0.0053333333
A17: 46235 | B17: 150 | C17: 5 | D17: BIT2ME | E17: 29531 | F17: =IF(Tabla13[[#This Row],[CANTIDAD]]=0,"",(Tabla13[[#This Row],[EUROS]]+Tabla13[[#This Row],[COMISION]])/Tabla13[[#This Row],[CANTIDAD]]) -> 0.0052487217

Sheet TRADES
A1: TRAZABILIDAD Y CONTABILIDAD
A2: CAMBIOS
A3: FECHA | B3: DOLARES | C3: MONEDA 1 | D3: MONEDA 2 | E3: VOLUMEN | F3: PRECIO TRADE
A4: 45874 | B4: 167 | C4: USDC | D4: THE | E4: 599 | F4: =Tabla110[[#This Row],[DOLARES]]/Tabla110[[#This Row],[VOLUMEN]] -> 0.278798
A5: 45965 | B5: 25 | C5: USDC | D5: ATOM | E5: 9.25 | F5: =Tabla110[[#This Row],[DOLARES]]/Tabla110[[#This Row],[VOLUMEN]] -> 2.7027027
A6: 45965 | B6: 25 | C6: USDC | D6: TIA | E6: 31 | F6: =Tabla110[[#This Row],[DOLARES]]/Tabla110[[#This Row],[VOLUMEN]] -> 0.80645161
A7: 45965 | B7: 25 | C7: USDC | D7: DOT | E7: 9.67 | F7: =Tabla110[[#This Row],[DOLARES]]/Tabla110[[#This Row],[VOLUMEN]] -> 2.5853154
A8: 45965 | B8: 25 | C8: USDC | D8: AVAX | E8: 1.5 | F8: =Tabla110[[#This Row],[DOLARES]]/Tabla110[[#This Row],[VOLUMEN]] -> 16.666667
A9: 45965 | B9: 25 | C9: USDC | D9: NEAR | E9: 13 | F9: =Tabla110[[#This Row],[DOLARES]]/Tabla110[[#This Row],[VOLUMEN]] -> 1.9230769
A10: 45997 | B10: 35 | C10: USDC | D10: ATOM | E10: 15.53 | F10: =Tabla110[[#This Row],[DOLARES]]/Tabla110[[#This Row],[VOLUMEN]] -> 2.2537025
A11: 45997 | B11: 35 | C11: USDC | D11: TIA | E11: 60.46 | F11: =Tabla110[[#This Row],[DOLARES]]/Tabla110[[#This Row],[VOLUMEN]] -> 0.57889514
A12: 45997 | B12: 35 | C12: USDC | D12: DOT | E12: 16.37 | F12: =Tabla110[[#This Row],[DOLARES]]/Tabla110[[#This Row],[VOLUMEN]] -> 2.1380574
A13: 45997 | B13: 35 | C13: USDC | D13: AVAX | E13: 2.62 | F13: =Tabla110[[#This Row],[DOLARES]]/Tabla110[[#This Row],[VOLUMEN]] -> 13.358779
A14: 45997 | B14: 35 | C14: USDC | D14: NEAR | E14: 20.38 | F14: =Tabla110[[#This Row],[DOLARES]]/Tabla110[[#This Row],[VOLUMEN]] -> 1.71737
